Workbook

Sheet Supuestos
B2: SUPUESTOS Y PARÁMETROS
B3: Pyme SAS - Empresa de Servicios | Contexto tributario colombiano 2026
B4: → Flujo de Caja | C4: → Dashboard | D4: → Calendario Tributario | E4: → Control de Cartera
B6: PARÁMETROS GENERALES
B7: Concepto | C7: Valor | D7: Notas / Referencia
B8: Saldo inicial de caja (COP) | C8: 50000000 | D8: Saldo en bancos al inicio del período
B9: Número de empleados | C9: 10 | D9: Planta de personal fija
B10: Salario promedio mensual (COP) | C10: 3500000 | D10: Salario base promedio
B11: Tarifa IVA general | C11: 0.19 | D11: Art. 468 E.T. — Tarifa general 19%
B12: % Clientes con retención en la fuente | C12: 0.7 | D12: Proporción de clientes que practican retención
B13: Tarifa retención en la fuente (servicios) | C13: 0.04 | D13: Art. 392 E.T. — Servicios generales 4%
B14: Tarifa retención de ICA (Bogotá, servicios) | C14: 0.00966 | D14: Varía según municipio y actividad
B15: Tarifa autorretención renta | C15: 0.008 | D15: Decreto 2201/2016 — 0.80%
B17: APORTES PARAFISCALES Y SEGURIDAD SOCIAL (% sobre salario)
B18: Concepto | C18: % Empleador | D18: Referencia legal
B19: Salud (EPS) | C19: 0.085 | D19: Ley 1122/2007 — 8.5% empleador
B20: Pensión (AFP) | C20: 0.12 | D20: Ley 797/2003 — 12% empleador
B21: ARL (Riesgo I - Servicios) | C21: 0.00522 | D21: Decreto 1295/1994 — Riesgo I
B22: Caja de Compensación | C22: 0.04 | D22: Ley 21/1982 — 4%
B23: ICBF | C23: 0.03 | D23: Ley 89/1988 — 3% (si aplica, >10 SMMLV nómina)
B24: SENA | C24: 0.02 | D24: Ley 21/1982 — 2% (si aplica, >10 SMMLV nómina)
B25: TOTAL CARGA PATRONAL | C25: =SUM(C19:C24) -> 0.30022
B27: PRESTACIONES SOCIALES (% sobre salario)
B28: Concepto | C28: % Provisión | D28: Referencia legal
B29: Cesantías | C29: 0.0833 | D29: CST Art. 249 — 8.33%
B30: Intereses sobre cesantías | C30: 0.01 | D30: Ley 52/1975 — 1% (12% anual / 12)
B31: Prima de servicios | C31: 0.0833 | D31: CST Art. 306 — 8.33%
B32: Vacaciones | C32: 0.0417 | D32: CST Art. 186 — 4.17%
B33: TOTAL PROVISIÓN PRESTACIONES | C33: =SUM(C29:C32) -> 0.2183
B35: Nota: Las celdas en azul son datos de entrada editables. Modifique los valores según su empresa.
B36: Generado: 2026-04-02 | Fuente: Estatuto Tributario Colombia, CST, normativa vigente 2026

Sheet Flujo de Caja
B2: FLUJO DE CAJA PROYECTADO — PYME SAS (SERVICIOS)
B3: Proyección mensual 12 meses | Cifras en COP | Período: Abril 2026 – Marzo 2027
B4: → Supuestos | C4: → Dashboard | D4: → Calendario Tributario | E4: → Control de Cartera
B5: CONCEPTO | C5: Abr-26 | D5: May-26 | E5: Jun-26 | F5: Jul-26 | G5: Ago-26 | H5: Sep-26 | I5: Oct-26 | J5: Nov-26 | K5: Dic-26 | L5: Ene-27 | M5: Feb-27 | N5: Mar-27 | O5: TOTAL ANUAL
B6: SALDO INICIAL DE CAJA | C6: =Supuestos!C8 -> 50000000 | D6: =C96 -> -3148200 | E6: =D96 -> -56296400 | F6: =E96 -> -109444600 | G6: =F96 -> -162592800 | H6: =G96 -> -215741000 | I6: =H96 -> -268889200 | J6: =I96 -> -322037400 | K6: =J96 -> -375185600 | ... N6: =M96 -> -534630200 | O6: =C6 -> 50000000
B8: A. INGRESOS OPERACIONALES
B9: A1. Recaudo por servicios prestados
B10: Servicios de consultoría
B11: Servicios profesionales / outsourcing
B12: Capacitaciones y formación
B13: Otros servicios
B14: Subtotal Ingresos Brutos (sin IVA) | C14: =C10+C11+C12+C13 -> 0 | D14: =D10+D11+D12+D13 -> 0 | E14: =E10+E11+E12+E13 -> 0 | F14: =F10+F11+F12+F13 -> 0 | G14: =G10+G11+G12+G13 -> 0 | H14: =H10+H11+H12+H13 -> 0 | I14: =I10+I11+I12+I13 -> 0 | J14: =J10+J11+J12+J13 -> 0 | ... O14: =O10+O11+O12+O13 -> 0
B15: (+) IVA cobrado sobre servicios (19%) | C15: =C14*Supuestos!$C$11 -> 0 | D15: =D14*Supuestos!$C$11 -> 0 | E15: =E14*Supuestos!$C$11 -> 0 | F15: =F14*Supuestos!$C$11 -> 0 | G15: =G14*Supuestos!$C$11 -> 0 | H15: =H14*Supuestos!$C$11 -> 0 | I15: =I14*Supuestos!$C$11 -> 0 | J15: =J14*Supuestos!$C$11 -> 0 | ... O15: =O14*Supuestos!$C$11 -> 0
B16: (-) Retención en la fuente practicada por clientes | C16: =-C14*Supuestos!$C$12*Supuestos!$C$13 -> 0 | D16: =-D14*Supuestos!$C$12*Supuestos!$C$13 -> 0 | E16: =-E14*Supuestos!$C$12*Supuestos!$C$13 -> 0 | F16: =-F14*Supuestos!$C$12*Supuestos!$C$13 -> 0 | G16: =-G14*Supuestos!$C$12*Supuestos!$C$13 -> 0 | H16: =-H14*Supuestos!$C$12*Supuestos!$C$13 -> 0 | I16: =-I14*Supuestos!$C$12*Supuestos!$C$13 -> 0 | J16: =-J14*Supuestos!$C$12*Supuestos!$C$13 -> 0 | ... O16: =-O14*Supuestos!$C$12*Supuestos!$C$13 -> 0
B17: (-) Retención de ICA practicada por clientes | C17: =-C14*Supuestos!$C$14 -> 0 | D17: =-D14*Supuestos!$C$14 -> 0 | E17: =-E14*Supuestos!$C$14 -> 0 | F17: =-F14*Supuestos!$C$14 -> 0 | G17: =-G14*Supuestos!$C$14 -> 0 | H17: =-H14*Supuestos!$C$14 -> 0 | I17: =-I14*Supuestos!$C$14 -> 0 | J17: =-J14*Supuestos!$C$14 -> 0 | ... O17: =-O14*Supuestos!$C$14 -> 0
B18: TOTAL INGRESOS RECIBIDOS EN EFECTIVO | C18: =C14+C15+C16+C17 -> 0 | D18: =D14+D15+D16+D17 -> 0 | E18: =E14+E15+E16+E17 -> 0 | F18: =F14+F15+F16+F17 -> 0 | G18: =G14+G15+G16+G17 -> 0 | H18: =H14+H15+H16+H17 -> 0 | I18: =I14+I15+I16+I17 -> 0 | J18: =J14+J15+J16+J17 -> 0 | ... O18: =O14+O15+O16+O17 -> 0
B20: A2. Otros ingresos de efectivo
B21: Rendimientos financieros
B22: Recuperación de cartera vencida
B23: Préstamos / créditos recibidos
B24: Aportes de socios
B25: Otros ingresos no operacionales
B26: TOTAL OTROS INGRESOS | C26: =C21+C22+C23+C24+C25 -> 0 | D26: =D21+D22+D23+D24+D25 -> 0 | E26: =E21+E22+E23+E24+E25 -> 0 | F26: =F21+F22+F23+F24+F25 -> 0 | G26: =G21+G22+G23+G24+G25 -> 0 | H26: =H21+H22+H23+H24+H25 -> 0 | I26: =I21+I22+I23+I24+I25 -> 0 | J26: =J21+J22+J23+J24+J25 -> 0 | ... O26: =O21+O22+O23+O24+O25 -> 0
B28: ═ TOTAL ENTRADAS DE EFECTIVO | C28: =C18+C26 -> 0 | D28: =D18+D26 -> 0 | E28: =E18+E26 -> 0 | F28: =F18+F26 -> 0 | G28: =G18+G26 -> 0 | H28: =H18+H26 -> 0 | I28: =I18+I26 -> 0 | J28: =J18+J26 -> 0 | ... O28: =O18+O26 -> 0
B30: B. EGRESOS (SALIDAS DE EFECTIVO)
B31: B1. Nómina y carga laboral
B32: Salarios base | C32: =Supuestos!$C$9*Supuestos!$C$10 -> 35000000 | D32: =Supuestos!$C$9*Supuestos!$C$10 -> 35000000 | E32: =Supuestos!$C$9*Supuestos!$C$10 -> 35000000 | F32: =Supuestos!$C$9*Supuestos!$C$10 -> 35000000 | G32: =Supuestos!$C$9*Supuestos!$C$10 -> 35000000 | H32: =Supuestos!$C$9*Supuestos!$C$10 -> 35000000 | I32: =Supuestos!$C$9*Supuestos!$C$10 -> 35000000 | J32: =Supuestos!$C$9*Supuestos!$C$10 -> 35000000 | ... O32: =Supuestos!$C$9*Supuestos!$C$10 -> 35000000
B33: Auxilio de transporte
B34: Horas extras y recargos
B35: Comisiones e incentivos
B36: Base salarial para aportes | C36: =C32+C34+C35 -> 35000000 | D36: =D32+D34+D35 -> 35000000 | E36: =E32+E34+E35 -> 35000000 | F36: =F32+F34+F35 -> 35000000 | G36: =G32+G34+G35 -> 35000000 | H36: =H32+H34+H35 -> 35000000 | I36: =I32+I34+I35 -> 35000000 | J36: =J32+J34+J35 -> 35000000 | ... O36: =O32+O34+O35 -> 35000000
B37: Salud (EPS) — 8.5% | C37: =C36*Supuestos!$C$19 -> 2975000 | D37: =D36*Supuestos!$C$19 -> 2975000 | E37: =E36*Supuestos!$C$19 -> 2975000 | F37: =F36*Supuestos!$C$19 -> 2975000 | G37: =G36*Supuestos!$C$19 -> 2975000 | H37: =H36*Supuestos!$C$19 -> 2975000 | I37: =I36*Supuestos!$C$19 -> 2975000 | J37: =J36*Supuestos!$C$19 -> 2975000 | ... O37: =O36*Supuestos!$C$19 -> 2975000
B38: Pensión (AFP) — 12% | C38: =C36*Supuestos!$C$20 -> 4200000 | D38: =D36*Supuestos!$C$20 -> 4200000 | E38: =E36*Supuestos!$C$20 -> 4200000 | F38: =F36*Supuestos!$C$20 -> 4200000 | G38: =G36*Supuestos!$C$20 -> 4200000 | H38: =H36*Supuestos!$C$20 -> 4200000 | I38: =I36*Supuestos!$C$20 -> 4200000 | J38: =J36*Supuestos!$C$20 -> 4200000 | ... O38: =O36*Supuestos!$C$20 -> 4200000
B39: ARL — Riesgo I | C39: =C36*Supuestos!$C$21 -> 182700 | D39: =D36*Supuestos!$C$21 -> 182700 | E39: =E36*Supuestos!$C$21 -> 182700 | F39: =F36*Supuestos!$C$21 -> 182700 | G39: =G36*Supuestos!$C$21 -> 182700 | H39: =H36*Supuestos!$C$21 -> 182700 | I39: =I36*Supuestos!$C$21 -> 182700 | J39: =J36*Supuestos!$C$21 -> 182700 | ... O39: =O36*Supuestos!$C$21 -> 182700
B40: Caja de Compensación — 4% | C40: =C36*Supuestos!$C$22 -> 1400000 | D40: =D36*Supuestos!$C$22 -> 1400000 | E40: =E36*Supuestos!$C$22 -> 1400000 | F40: =F36*Supuestos!$C$22 -> 1400000 | G40: =G36*Supuestos!$C$22 -> 1400000 | H40: =H36*Supuestos!$C$22 -> 1400000 | I40: =I36*Supuestos!$C$22 -> 1400000 | J40: =J36*Supuestos!$C$22 -> 1400000 | ... O40: =O36*Supuestos!$C$22 -> 1400000
B41: ICBF — 3% | C41: =C36*Supuestos!$C$23 -> 1050000 | D41: =D36*Supuestos!$C$23 -> 1050000 | E41: =E36*Supuestos!$C$23 -> 1050000 | F41: =F36*Supuestos!$C$23 -> 1050000 | G41: =G36*Supuestos!$C$23 -> 1050000 | H41: =H36*Supuestos!$C$23 -> 1050000 | I41: =I36*Supuestos!$C$23 -> 1050000 | J41: =J36*Supuestos!$C$23 -> 1050000 | ... O41: =O36*Supuestos!$C$23 -> 1050000
B42: SENA — 2% | C42: =C36*Supuestos!$C$24 -> 700000 | D42: =D36*Supuestos!$C$24 -> 700000 | E42: =E36*Supuestos!$C$24 -> 700000 | F42: =F36*Supuestos!$C$24 -> 700000 | G42: =G36*Supuestos!$C$24 -> 700000 | H42: =H36*Supuestos!$C$24 -> 700000 | I42: =I36*Supuestos!$C$24 -> 700000 | J42: =J36*Supuestos!$C$24 -> 700000 | ... O42: =O36*Supuestos!$C$24 -> 700000
B43: Cesantías — 8.33% | C43: =C36*Supuestos!$C$29 -> 2915500 | D43: =D36*Supuestos!$C$29 -> 2915500 | E43: =E36*Supuestos!$C$29 -> 2915500 | F43: =F36*Supuestos!$C$29 -> 2915500 | G43: =G36*Supuestos!$C$29 -> 2915500 | H43: =H36*Supuestos!$C$29 -> 2915500 | I43: =I36*Supuestos!$C$29 -> 2915500 | J43: =J36*Supuestos!$C$29 -> 2915500 | ... O43: =O36*Supuestos!$C$29 -> 2915500
B44: Intereses sobre cesantías — 1% | C44: =C36*Supuestos!$C$30 -> 350000 | D44: =D36*Supuestos!$C$30 -> 350000 | E44: =E36*Supuestos!$C$30 -> 350000 | F44: =F36*Supuestos!$C$30 -> 350000 | G44: =G36*Supuestos!$C$30 -> 350000 | H44: =H36*Supuestos!$C$30 -> 350000 | I44: =I36*Supuestos!$C$30 -> 350000 | J44: =J36*Supuestos!$C$30 -> 350000 | ... O44: =O36*Supuestos!$C$30 -> 350000
B45: Prima de servicios — 8.33% | C45: =C36*Supuestos!$C$31 -> 2915500 | D45: =D36*Supuestos!$C$31 -> 2915500 | E45: =E36*Supuestos!$C$31 -> 2915500 | F45: =F36*Supuestos!$C$31 -> 2915500 | G45: =G36*Supuestos!$C$31 -> 2915500 | H45: =H36*Supuestos!$C$31 -> 2915500 | I45: =I36*Supuestos!$C$31 -> 2915500 | J45: =J36*Supuestos!$C$31 -> 2915500 | ... O45: =O36*Supuestos!$C$31 -> 2915500
...

Sheet Dashboard
B2: DASHBOARD — RESUMEN FLUJO DE CAJA
B3: Indicadores clave del período Abril 2026 – Marzo 2027
B4: → Supuestos | C4: → Flujo de Caja | D4: → Calendario Tributario | E4: → Control de Cartera
B5: Saldo Inicial | C5: Total Entradas (Anual) | D5: Total Salidas (Anual) | E5: Flujo Neto (Anual) | F5: Saldo Final Proyectado
B6: ='Flujo de Caja'!C6 -> 50000000 | C6: ='Flujo de Caja'!O28 -> 0 | D6: ='Flujo de Caja'!O93 -> 53148200 | E6: ='Flujo de Caja'!O95 -> -53148200 | F6: ='Flujo de Caja'!O96 -> -587778400
B8: RESUMEN MENSUAL
B9: Mes | C9: Entradas | D9: Salidas | E9: Flujo Neto | F9: Saldo Final
B10: Abr-26 | C10: ='Flujo de Caja'!C28 -> 0 | D10: ='Flujo de Caja'!C93 -> 53148200 | E10: ='Flujo de Caja'!C95 -> -53148200 | F10: ='Flujo de Caja'!C96 -> -3148200
B11: May-26 | C11: ='Flujo de Caja'!D28 -> 0 | D11: ='Flujo de Caja'!D93 -> 53148200 | E11: ='Flujo de Caja'!D95 -> -53148200 | F11: ='Flujo de Caja'!D96 -> -56296400
B12: Jun-26 | C12: ='Flujo de Caja'!E28 -> 0 | D12: ='Flujo de Caja'!E93 -> 53148200 | E12: ='Flujo de Caja'!E95 -> -53148200 | F12: ='Flujo de Caja'!E96 -> -109444600
B13: Jul-26 | C13: ='Flujo de Caja'!F28 -> 0 | D13: ='Flujo de Caja'!F93 -> 53148200 | E13: ='Flujo de Caja'!F95 -> -53148200 | F13: ='Flujo de Caja'!F96 -> -162592800
B14: Ago-26 | C14: ='Flujo de Caja'!G28 -> 0 | D14: ='Flujo de Caja'!G93 -> 53148200 | E14: ='Flujo de Caja'!G95 -> -53148200 | F14: ='Flujo de Caja'!G96 -> -215741000
B15: Sep-26 | C15: ='Flujo de Caja'!H28 -> 0 | D15: ='Flujo de Caja'!H93 -> 53148200 | E15: ='Flujo de Caja'!H95 -> -53148200 | F15: ='Flujo de Caja'!H96 -> -268889200
B16: Oct-26 | C16: ='Flujo de Caja'!I28 -> 0 | D16: ='Flujo de Caja'!I93 -> 53148200 | E16: ='Flujo de Caja'!I95 -> -53148200 | F16: ='Flujo de Caja'!I96 -> -322037400
B17: Nov-26 | C17: ='Flujo de Caja'!J28 -> 0 | D17: ='Flujo de Caja'!J93 -> 53148200 | E17: ='Flujo de Caja'!J95 -> -53148200 | F17: ='Flujo de Caja'!J96 -> -375185600
B18: Dic-26 | C18: ='Flujo de Caja'!K28 -> 0 | D18: ='Flujo de Caja'!K93 -> 53148200 | E18: ='Flujo de Caja'!K95 -> -53148200 | F18: ='Flujo de Caja'!K96 -> -428333800
B19: Ene-27 | C19: ='Flujo de Caja'!L28 -> 0 | D19: ='Flujo de Caja'!L93 -> 53148200 | E19: ='Flujo de Caja'!L95 -> -53148200 | F19: ='Flujo de Caja'!L96 -> -481482000
B20: Feb-27 | C20: ='Flujo de Caja'!M28 -> 0 | D20: ='Flujo de Caja'!M93 -> 53148200 | E20: ='Flujo de Caja'!M95 -> -53148200 | F20: ='Flujo de Caja'!M96 -> -534630200
B21: Mar-27 | C21: ='Flujo de Caja'!N28 -> 0 | D21: ='Flujo de Caja'!N93 -> 53148200 | E21: ='Flujo de Caja'!N95 -> -53148200 | F21: ='Flujo de Caja'!N96 -> -587778400

Sheet Calendario Tributario
B2: CALENDARIO TRIBUTARIO 2026–2027 — WE4LABS S.A.S.
B3: Domicilio: Cali | Actividad: Servicios de tecnología | Fuente: DIAN y Alcaldía de Cali (Res. 4131.010.1.0607/2025)
B4: → Flujo de Caja | C4: → Supuestos | D4: → Dashboard | E4: → Cartera
B5: ⚙ INSTRUCCIÓN: Ingresa el último dígito de tu NIT (sin dígito de verificación) en la celda amarilla para que las fechas se ajusten automáticamente.
B6: Último dígito NIT: | C6: 0 | D6: Ingresa 0, 1, 2 … 9 (sin dígito de verificación). Ejemplo: NIT 900.123.456-7 → ingresa 6
B8: CONVENCIONES
B9: VENCIDO | D9: PRÓXIMO (≤7 días) | F9: AL DÍA | H9: PAGADO
B11: Mes | C11: Obligación | D11: Período cubierto | E11: Fecha límite | F11: Estado | G11: Fecha pago real | H11: Valor COP | I11: Notas / Formulario
B12: Feb-26 | C12: Retención en la fuente | D12: Feb-26 (por Ene) | E12: =IFERROR(CHOOSE(IF(C6=0,10,C6),"10-feb-26","11-feb-26","12-feb-26","13-feb-26","16-feb-26","17-feb-26","18-feb-26","19-feb-26","20-feb-26","23-feb-26"),"10-feb-26") -> 23-feb-26 | F12: =IF(G12="PAGADO","PAGADO",IF(ISNUMBER(DATEVALUE(E12)),IF(TODAY()>DATEVALUE(E12),"VENCIDO",IF(TODAY()>=DATEVALUE(E12)-7,"PRÓXIMO (≤7 días)","AL DÍA")),"AL DÍA")) -> VENCIDO | I12: Formulario 350 — DIAN. Presentar aunque no haya retenciones del mes.
B13: Mar-26 | C13: Retención en la fuente | D13: Mar-26 (por Feb) | E13: =IFERROR(CHOOSE(IF(C6=0,10,C6),"10-mar-26","11-mar-26","12-mar-26","13-mar-26","16-mar-26","17-mar-26","18-mar-26","19-mar-26","20-mar-26","24-mar-26"),"10-mar-26") -> 24-mar-26 | F13: =IF(G13="PAGADO","PAGADO",IF(ISNUMBER(DATEVALUE(E13)),IF(TODAY()>DATEVALUE(E13),"VENCIDO",IF(TODAY()>=DATEVALUE(E13)-7,"PRÓXIMO (≤7 días)","AL DÍA")),"AL DÍA")) -> VENCIDO | I13: Formulario 350 — DIAN. Presentar aunque no haya retenciones del mes.
B14: Mar-26 | C14: Renovación Matrícula Mercantil | D14: Vigencia 2026 | E14: 31-mar-26 | F14: =IF(G14="PAGADO","PAGADO",IF(ISNUMBER(DATEVALUE(E14)),IF(TODAY()>DATEVALUE(E14),"VENCIDO",IF(TODAY()>=DATEVALUE(E14)-7,"PRÓXIMO (≤7 días)","AL DÍA")),"AL DÍA")) -> VENCIDO | I14: Cámara de Comercio de Cali. Antes del 31 de marzo. Si aplica Ley 1780: $0 primer año.
B15: Mar-26 | C15: Asamblea General de Accionistas | D15: Año 2025 | E15: 31-mar-26 | F15: =IF(G15="PAGADO","PAGADO",IF(ISNUMBER(DATEVALUE(E15)),IF(TODAY()>DATEVALUE(E15),"VENCIDO",IF(TODAY()>=DATEVALUE(E15)-7,"PRÓXIMO (≤7 días)","AL DÍA")),"AL DÍA")) -> VENCIDO | I15: CST Art. 422. Reunión ordinaria antes del 31 de marzo. Aprobar estados financieros y acta firmada.
B16: Abr-26 | C16: Retención en la fuente | D16: Abr-26 (por Mar) | E16: =IFERROR(CHOOSE(IF(C6=0,10,C6),"13-abr-26","14-abr-26","15-abr-26","16-abr-26","17-abr-26","20-abr-26","21-abr-26","22-abr-26","23-abr-26","24-abr-26"),"13-abr-26") -> 24-abr-26 | F16: =IF(G16="PAGADO","PAGADO",IF(ISNUMBER(DATEVALUE(E16)),IF(TODAY()>DATEVALUE(E16),"VENCIDO",IF(TODAY()>=DATEVALUE(E16)-7,"PRÓXIMO (≤7 días)","AL DÍA")),"AL DÍA")) -> AL DÍA | I16: Formulario 350 — DIAN. Presentar aunque no haya retenciones del mes.
B17: May-26 | C17: Retención en la fuente | D17: May-26 (por Abr) | E17: =IFERROR(CHOOSE(IF(C6=0,10,C6),"12-may-26","13-may-26","14-may-26","15-may-26","19-may-26","20-may-26","21-may-26","22-may-26","25-may-26","26-may-26"),"12-may-26") -> 26-may-26 | F17: =IF(G17="PAGADO","PAGADO",IF(ISNUMBER(DATEVALUE(E17)),IF(TODAY()>DATEVALUE(E17),"VENCIDO",IF(TODAY()>=DATEVALUE(E17)-7,"PRÓXIMO (≤7 días)","AL DÍA")),"AL DÍA")) -> AL DÍA | I17: Formulario 350 — DIAN. Presentar aunque no haya retenciones del mes.
B18: May-26 | C18: IVA cuatrimestral (responsable régimen común) | D18: Ene–Abr 2026 | E18: =IFERROR(CHOOSE(IF(C6=0,10,C6),"12-may-26","13-may-26","14-may-26","15-may-26","19-may-26","20-may-26","21-may-26","22-may-26","25-may-26","26-may-26"),"12-may-26") -> 26-may-26 | F18: =IF(G18="PAGADO","PAGADO",IF(ISNUMBER(DATEVALUE(E18)),IF(TODAY()>DATEVALUE(E18),"VENCIDO",IF(TODAY()>=DATEVALUE(E18)-7,"PRÓXIMO (≤7 días)","AL DÍA")),"AL DÍA")) -> AL DÍA | I18: Formulario 300 — DIAN. Empresa nueva/pequeña: periocidad cuatrimestral si ingresos < $4.329M.
B19: May-26 | C19: Impuesto de Renta — Personas Jurídicas | D19: Año gravable 2025 — 1ª cuota + declaración | E19: =IFERROR(CHOOSE(IF(C6=0,10,C6),"12-may-26","13-may-26","14-may-26","15-may-26","19-may-26","20-may-26","21-may-26","22-may-26","25-may-26","26-may-26"),"12-may-26") -> 26-may-26 | F19: =IF(G19="PAGADO","PAGADO",IF(ISNUMBER(DATEVALUE(E19)),IF(TODAY()>DATEVALUE(E19),"VENCIDO",IF(TODAY()>=DATEVALUE(E19)-7,"PRÓXIMO (≤7 días)","AL DÍA")),"AL DÍA")) -> AL DÍA | I19: Formulario 110. Primera cuota y presentación declaración de renta.
B20: May-26 | C20: ICA Cali — Declaración anual (Año gravable 2025) | D20: Año gravable 2025 | E20: 04-may-26 | F20: =IF(G20="PAGADO","PAGADO",IF(ISNUMBER(DATEVALUE(E20)),IF(TODAY()>DATEVALUE(E20),"VENCIDO",IF(TODAY()>=DATEVALUE(E20)-7,"PRÓXIMO (≤7 días)","AL DÍA")),"AL DÍA")) -> AL DÍA | I20: Alcaldía Cali. Ingresos < 32.998 UVT → declaración anual. Formulario municipal.
B21: Jun-26 | C21: Retención en la fuente | D21: Jun-26 (por May) | E21: =IFERROR(CHOOSE(IF(C6=0,10,C6),"10-jun-26","11-jun-26","12-jun-26","16-jun-26","17-jun-26","18-jun-26","19-jun-26","22-jun-26","23-jun-26","24-jun-26"),"10-jun-26") -> 24-jun-26 | F21: =IF(G21="PAGADO","PAGADO",IF(ISNUMBER(DATEVALUE(E21)),IF(TODAY()>DATEVALUE(E21),"VENCIDO",IF(TODAY()>=DATEVALUE(E21)-7,"PRÓXIMO (≤7 días)","AL DÍA")),"AL DÍA")) -> AL DÍA | I21: Formulario 350 — DIAN. Presentar aunque no haya retenciones del mes.
B22: Jul-26 | C22: Retención en la fuente | D22: Jul-26 (por Jun) | E22: =IFERROR(CHOOSE(IF(C6=0,10,C6),"09-jul-26","10-jul-26","13-jul-26","14-jul-26","15-jul-26","16-jul-26","17-jul-26","21-jul-26","22-jul-26","23-jul-26"),"09-jul-26") -> 23-jul-26 | F22: =IF(G22="PAGADO","PAGADO",IF(ISNUMBER(DATEVALUE(E22)),IF(TODAY()>DATEVALUE(E22),"VENCIDO",IF(TODAY()>=DATEVALUE(E22)-7,"PRÓXIMO (≤7 días)","AL DÍA")),"AL DÍA")) -> AL DÍA | I22: Formulario 350 — DIAN. Presentar aunque no haya retenciones del mes.
B23: Jul-26 | C23: Impuesto de Renta — Personas Jurídicas | D23: Año gravable 2025 — 2ª cuota | E23: =IFERROR(CHOOSE(IF(C6=0,10,C6),"09-jul-26","10-jul-26","13-jul-26","14-jul-26","15-jul-26","16-jul-26","17-jul-26","21-jul-26","22-jul-26","23-jul-26"),"09-jul-26") -> 23-jul-26 | F23: =IF(G23="PAGADO","PAGADO",IF(ISNUMBER(DATEVALUE(E23)),IF(TODAY()>DATEVALUE(E23),"VENCIDO",IF(TODAY()>=DATEVALUE(E23)-7,"PRÓXIMO (≤7 días)","AL DÍA")),"AL DÍA")) -> AL DÍA | I23: Pago segunda cuota impuesto de renta. Formulario 490.
B24: Jul-26 | C24: Información exógena municipal — Cali | D24: Año gravable 2025 | E24: 22-jul-26 | F24: =IF(G24="PAGADO","PAGADO",IF(ISNUMBER(DATEVALUE(E24)),IF(TODAY()>DATEVALUE(E24),"VENCIDO",IF(TODAY()>=DATEVALUE(E24)-7,"PRÓXIMO (≤7 días)","AL DÍA")),"AL DÍA")) -> AL DÍA | I24: Alcaldía Cali. Aplica si ingresos ≥ 3.500 UVT al 31-dic-2025. Plazos 22 jul – 14 ago 2026.
B25: Ago-26 | C25: Retención en la fuente | D25: Ago-26 (por Jul) | E25: =IFERROR(CHOOSE(IF(C6=0,10,C6),"12-ago-26","13-ago-26","14-ago-26","18-ago-26","19-ago-26","20-ago-26","21-ago-26","24-ago-26","25-ago-26","26-ago-26"),"12-ago-26") -> 26-ago-26 | F25: =IF(G25="PAGADO","PAGADO",IF(ISNUMBER(DATEVALUE(E25)),IF(TODAY()>DATEVALUE(E25),"VENCIDO",IF(TODAY()>=DATEVALUE(E25)-7,"PRÓXIMO (≤7 días)","AL DÍA")),"AL DÍA")) -> AL DÍA | I25: Formulario 350 — DIAN. Presentar aunque no haya retenciones del mes.
B26: Sep-26 | C26: Retención en la fuente | D26: Sep-26 (por Ago) | E26: =IFERROR(CHOOSE(IF(C6=0,10,C6),"09-sep-26","10-sep-26","11-sep-26","14-sep-26","15-sep-26","16-sep-26","17-sep-26","18-sep-26","21-sep-26","22-sep-26"),"09-sep-26") -> 22-sep-26 | F26: =IF(G26="PAGADO","PAGADO",IF(ISNUMBER(DATEVALUE(E26)),IF(TODAY()>DATEVALUE(E26),"VENCIDO",IF(TODAY()>=DATEVALUE(E26)-7,"PRÓXIMO (≤7 días)","AL DÍA")),"AL DÍA")) -> AL DÍA | I26: Formulario 350 — DIAN. Presentar aunque no haya retenciones del mes.
B27: Sep-26 | C27: IVA cuatrimestral (responsable régimen común) | D27: May–Ago 2026 | E27: =IFERROR(CHOOSE(IF(C6=0,10,C6),"09-sep-26","10-sep-26","11-sep-26","14-sep-26","15-sep-26","16-sep-26","17-sep-26","18-sep-26","21-sep-26","22-sep-26"),"09-sep-26") -> 22-sep-26 | F27: =IF(G27="PAGADO","PAGADO",IF(ISNUMBER(DATEVALUE(E27)),IF(TODAY()>DATEVALUE(E27),"VENCIDO",IF(TODAY()>=DATEVALUE(E27)-7,"PRÓXIMO (≤7 días)","AL DÍA")),"AL DÍA")) -> AL DÍA | I27: Formulario 300 — DIAN. Empresa nueva/pequeña: periocidad cuatrimestral si ingresos < $4.329M.
B28: Oct-26 | C28: Retención en la fuente | D28: Oct-26 (por Sep) | E28: =IFERROR(CHOOSE(IF(C6=0,10,C6),"09-oct-26","13-oct-26","14-oct-26","15-oct-26","16-oct-26","19-oct-26","20-oct-26","21-oct-26","22-oct-26","23-oct-26"),"09-oct-26") -> 23-oct-26 | F28: =IF(G28="PAGADO","PAGADO",IF(ISNUMBER(DATEVALUE(E28)),IF(TODAY()>DATEVALUE(E28),"VENCIDO",IF(TODAY()>=DATEVALUE(E28)-7,"PRÓXIMO (≤7 días)","AL DÍA")),"AL DÍA")) -> AL DÍA | I28: Formulario 350 — DIAN. Presentar aunque no haya retenciones del mes.
B29: Nov-26 | C29: Retención en la fuente | D29: Nov-26 (por Oct) | E29: =IFERROR(CHOOSE(IF(C6=0,10,C6),"11-nov-26","12-nov-26","13-nov-26","17-nov-26","18-nov-26","19-nov-26","20-nov-26","23-nov-26","24-nov-26","25-nov-26"),"11-nov-26") -> 25-nov-26 | F29: =IF(G29="PAGADO","PAGADO",IF(ISNUMBER(DATEVALUE(E29)),IF(TODAY()>DATEVALUE(E29),"VENCIDO",IF(TODAY()>=DATEVALUE(E29)-7,"PRÓXIMO (≤7 días)","AL DÍA")),"AL DÍA")) -> AL DÍA | I29: Formulario 350 — DIAN. Presentar aunque no haya retenciones del mes.
B30: Dic-26 | C30: Retención en la fuente | D30: Dic-26 (por Nov) | E30: =IFERROR(CHOOSE(IF(C6=0,10,C6),"10-dic-26","11-dic-26","14-dic-26","15-dic-26","16-dic-26","17-dic-26","18-dic-26","21-dic-26","22-dic-26","23-dic-26"),"10-dic-26") -> 23-dic-26 | F30: =IF(G30="PAGADO","PAGADO",IF(ISNUMBER(DATEVALUE(E30)),IF(TODAY()>DATEVALUE(E30),"VENCIDO",IF(TODAY()>=DATEVALUE(E30)-7,"PRÓXIMO (≤7 días)","AL DÍA")),"AL DÍA")) -> AL DÍA | I30: Formulario 350 — DIAN. Presentar aunque no haya retenciones del mes.
B31: Ene-27 | C31: Retención en la fuente | D31: Ene-27 (por Dic) | E31: =IFERROR(CHOOSE(IF(C6=0,10,C6),"13-ene-27","14-ene-27","15-ene-27","18-ene-27","19-ene-27","20-ene-27","21-ene-27","22-ene-27","25-ene-27","26-ene-27"),"13-ene-27") -> 26-ene-27 | F31: =IF(G31="PAGADO","PAGADO",IF(ISNUMBER(DATEVALUE(E31)),IF(TODAY()>DATEVALUE(E31),"VENCIDO",IF(TODAY()>=DATEVALUE(E31)-7,"PRÓXIMO (≤7 días)","AL DÍA")),"AL DÍA")) -> AL DÍA | I31: Formulario 350 — DIAN. Presentar aunque no haya retenciones del mes.
B32: Ene-27 | C32: IVA cuatrimestral (responsable régimen común) | D32: Sep–Dic 2026 | E32: =IFERROR(CHOOSE(IF(C6=0,10,C6),"13-ene-27","14-ene-27","15-ene-27","18-ene-27","19-ene-27","20-ene-27","21-ene-27","22-ene-27","25-ene-27","26-ene-27"),"13-ene-27") -> 26-ene-27 | F32: =IF(G32="PAGADO","PAGADO",IF(ISNUMBER(DATEVALUE(E32)),IF(TODAY()>DATEVALUE(E32),"VENCIDO",IF(TODAY()>=DATEVALUE(E32)-7,"PRÓXIMO (≤7 días)","AL DÍA")),"AL DÍA")) -> AL DÍA | I32: Formulario 300 — DIAN. Empresa nueva/pequeña: periocidad cuatrimestral si ingresos < $4.329M.
B34: TOTAL ESTIMADO OBLIGACIONES TRIBUTARIAS (anual) | H34: =SUM(H12:H32) -> 0
B36: Fuentes: DIAN — Decreto 2229/2023 y Resolución 000165/2023 | Alcaldía de Cali — Resolución 4131.010.1.0607/2025 | Código Sustantivo del Trabajo
B37: Generado: 2026-04-03 | Ingresa 'PAGADO' en la columna Estado para marcar una obligación como cumplida.

Sheet Control de Cartera
B2: CONTROL DE CARTERA / CUENTAS POR COBRAR — WE4LABS S.A.S.
B3: Seguimiento a facturas emitidas, recaudo efectivo y antigüedad de cartera
B4: → Flujo de Caja | C4: → Supuestos | D4: → Calendario Tributario
B6: Total facturado (bruto) | D6: Total IVA cobrado | F6: Total retenciones desc. | H6: Neto por cobrar | J6: Total recaudado | L6: Cartera vigente | N6: Cartera vencida
B7: =IFERROR(SUM(H7:H206),0) -> 6261700 | D7: =IFERROR(SUM(I7:I206),0) -> 475000 | F7: =IFERROR(SUM(J7:J206)+SUM(K7:K206),0) -> 2094150 | H7: =IFERROR(SUM(L7:L206),0) -> 3761700 | J7: =IFERROR(SUM(M7:M206),0) -> 2000000 | L7: =IFERROR(SUMIF(P7:P206,"VIGENTE",N7:N206),0) -> 880850 | N7: =IFERROR(SUMIF(P7:P206,"VENCIDA",N7:N206)+SUMIF(P7:P206,"CRÍTICA",N7:N206),0) -> 0
B9: # | C9: Cliente | D9: Descripción del servicio | E9: N° Factura | F9: Fecha emisión | G9: Fecha vencimiento | H9: Valor bruto | I9: IVA cobrado (19%) | J9: Retefuente desc. | K9: ReteICA desc. | L9: Neto a cobrar | M9: Pagado | N9: Saldo pendiente | O9: Días vencidos | P9: Estado | Q9: Observaciones
B10: 1 | C10: Stratech | D10: desarrollo de softaware | E10: 1 | F10: 46112 | G10: 46116 | H10: 2500000 | I10: =IF(H10<>"",H10*Supuestos!$C$11,"") -> 475000 | J10: =IF(H10<>"",H10*Supuestos!$C$12*Supuestos!$C$13,"") -> 70000 | K10: =IF(H10<>"",H10*Supuestos!$C$14,"") -> 24150 | L10: =IF(H10<>"",H10+I10-J10-K10,"") -> 2880850 | M10: 2000000 | N10: =IF(H10<>"",IF(M10<>"",L10-M10,L10),"") -> 880850 | O10: =IF(AND(H10<>"",N10>0,G10<>""),MAX(TODAY()-G10,0),"") -> 0 | P10: =IF(H10="","",IF(N10<=0,"COBRADA",IF(G10="","VIGENTE",IF(TODAY()<=G10,"VIGENTE",IF(TODAY()-G10<=30,"VENCIDA",IF(TODAY()-G10<=90,"CRÍTICA","CASTIGAR")))))) -> VIGENTE
B11: 2 | I11: =IF(H11<>"",H11*Supuestos!$C$11,"") | J11: =IF(H11<>"",H11*Supuestos!$C$12*Supuestos!$C$13,"") | K11: =IF(H11<>"",H11*Supuestos!$C$14,"") | L11: =IF(H11<>"",H11+I11-J11-K11,"") | N11: =IF(H11<>"",IF(M11<>"",L11-M11,L11),"") | O11: =IF(AND(H11<>"",N11>0,G11<>""),MAX(TODAY()-G11,0),"") | P11: =IF(H11="","",IF(N11<=0,"COBRADA",IF(G11="","VIGENTE",IF(TODAY()<=G11,"VIGENTE",IF(TODAY()-G11<=30,"VENCIDA",IF(TODAY()-G11<=90,"CRÍTICA","CASTIGAR"))))))
B12: 3 | I12: =IF(H12<>"",H12*Supuestos!$C$11,"") | J12: =IF(H12<>"",H12*Supuestos!$C$12*Supuestos!$C$13,"") | K12: =IF(H12<>"",H12*Supuestos!$C$14,"") | L12: =IF(H12<>"",H12+I12-J12-K12,"") | N12: =IF(H12<>"",IF(M12<>"",L12-M12,L12),"") | O12: =IF(AND(H12<>"",N12>0,G12<>""),MAX(TODAY()-G12,0),"") | P12: =IF(H12="","",IF(N12<=0,"COBRADA",IF(G12="","VIGENTE",IF(TODAY()<=G12,"VIGENTE",IF(TODAY()-G12<=30,"VENCIDA",IF(TODAY()-G12<=90,"CRÍTICA","CASTIGAR"))))))
B13: 4 | I13: =IF(H13<>"",H13*Supuestos!$C$11,"") | J13: =IF(H13<>"",H13*Supuestos!$C$12*Supuestos!$C$13,"") | K13: =IF(H13<>"",H13*Supuestos!$C$14,"") | L13: =IF(H13<>"",H13+I13-J13-K13,"") | N13: =IF(H13<>"",IF(M13<>"",L13-M13,L13),"") | O13: =IF(AND(H13<>"",N13>0,G13<>""),MAX(TODAY()-G13,0),"") | P13: =IF(H13="","",IF(N13<=0,"COBRADA",IF(G13="","VIGENTE",IF(TODAY()<=G13,"VIGENTE",IF(TODAY()-G13<=30,"VENCIDA",IF(TODAY()-G13<=90,"CRÍTICA","CASTIGAR"))))))
B14: 5 | I14: =IF(H14<>"",H14*Supuestos!$C$11,"") | J14: =IF(H14<>"",H14*Supuestos!$C$12*Supuestos!$C$13,"") | K14: =IF(H14<>"",H14*Supuestos!$C$14,"") | L14: =IF(H14<>"",H14+I14-J14-K14,"") | N14: =IF(H14<>"",IF(M14<>"",L14-M14,L14),"") | O14: =IF(AND(H14<>"",N14>0,G14<>""),MAX(TODAY()-G14,0),"") | P14: =IF(H14="","",IF(N14<=0,"COBRADA",IF(G14="","VIGENTE",IF(TODAY()<=G14,"VIGENTE",IF(TODAY()-G14<=30,"VENCIDA",IF(TODAY()-G14<=90,"CRÍTICA","CASTIGAR"))))))
B15: 6 | I15: =IF(H15<>"",H15*Supuestos!$C$11,"") | J15: =IF(H15<>"",H15*Supuestos!$C$12*Supuestos!$C$13,"") | K15: =IF(H15<>"",H15*Supuestos!$C$14,"") | L15: =IF(H15<>"",H15+I15-J15-K15,"") | N15: =IF(H15<>"",IF(M15<>"",L15-M15,L15),"") | O15: =IF(AND(H15<>"",N15>0,G15<>""),MAX(TODAY()-G15,0),"") | P15: =IF(H15="","",IF(N15<=0,"COBRADA",IF(G15="","VIGENTE",IF(TODAY()<=G15,"VIGENTE",IF(TODAY()-G15<=30,"VENCIDA",IF(TODAY()-G15<=90,"CRÍTICA","CASTIGAR"))))))
B16: 7 | I16: =IF(H16<>"",H16*Supuestos!$C$11,"") | J16: =IF(H16<>"",H16*Supuestos!$C$12*Supuestos!$C$13,"") | K16: =IF(H16<>"",H16*Supuestos!$C$14,"") | L16: =IF(H16<>"",H16+I16-J16-K16,"") | N16: =IF(H16<>"",IF(M16<>"",L16-M16,L16),"") | O16: =IF(AND(H16<>"",N16>0,G16<>""),MAX(TODAY()-G16,0),"") | P16: =IF(H16="","",IF(N16<=0,"COBRADA",IF(G16="","VIGENTE",IF(TODAY()<=G16,"VIGENTE",IF(TODAY()-G16<=30,"VENCIDA",IF(TODAY()-G16<=90,"CRÍTICA","CASTIGAR"))))))
B17: 8 | I17: =IF(H17<>"",H17*Supuestos!$C$11,"") | J17: =IF(H17<>"",H17*Supuestos!$C$12*Supuestos!$C$13,"") | K17: =IF(H17<>"",H17*Supuestos!$C$14,"") | L17: =IF(H17<>"",H17+I17-J17-K17,"") | N17: =IF(H17<>"",IF(M17<>"",L17-M17,L17),"") | O17: =IF(AND(H17<>"",N17>0,G17<>""),MAX(TODAY()-G17,0),"") | P17: =IF(H17="","",IF(N17<=0,"COBRADA",IF(G17="","VIGENTE",IF(TODAY()<=G17,"VIGENTE",IF(TODAY()-G17<=30,"VENCIDA",IF(TODAY()-G17<=90,"CRÍTICA","CASTIGAR"))))))
B18: 9 | I18: =IF(H18<>"",H18*Supuestos!$C$11,"") | J18: =IF(H18<>"",H18*Supuestos!$C$12*Supuestos!$C$13,"") | K18: =IF(H18<>"",H18*Supuestos!$C$14,"") | L18: =IF(H18<>"",H18+I18-J18-K18,"") | N18: =IF(H18<>"",IF(M18<>"",L18-M18,L18),"") | O18: =IF(AND(H18<>"",N18>0,G18<>""),MAX(TODAY()-G18,0),"") | P18: =IF(H18="","",IF(N18<=0,"COBRADA",IF(G18="","VIGENTE",IF(TODAY()<=G18,"VIGENTE",IF(TODAY()-G18<=30,"VENCIDA",IF(TODAY()-G18<=90,"CRÍTICA","CASTIGAR"))))))
B19: 10 | I19: =IF(H19<>"",H19*Supuestos!$C$11,"") | J19: =IF(H19<>"",H19*Supuestos!$C$12*Supuestos!$C$13,"") | K19: =IF(H19<>"",H19*Supuestos!$C$14,"") | L19: =IF(H19<>"",H19+I19-J19-K19,"") | N19: =IF(H19<>"",IF(M19<>"",L19-M19,L19),"") | O19: =IF(AND(H19<>"",N19>0,G19<>""),MAX(TODAY()-G19,0),"") | P19: =IF(H19="","",IF(N19<=0,"COBRADA",IF(G19="","VIGENTE",IF(TODAY()<=G19,"VIGENTE",IF(TODAY()-G19<=30,"VENCIDA",IF(TODAY()-G19<=90,"CRÍTICA","CASTIGAR"))))))
B20: 11 | I20: =IF(H20<>"",H20*Supuestos!$C$11,"") | J20: =IF(H20<>"",H20*Supuestos!$C$12*Supuestos!$C$13,"") | K20: =IF(H20<>"",H20*Supuestos!$C$14,"") | L20: =IF(H20<>"",H20+I20-J20-K20,"") | N20: =IF(H20<>"",IF(M20<>"",L20-M20,L20),"") | O20: =IF(AND(H20<>"",N20>0,G20<>""),MAX(TODAY()-G20,0),"") | P20: =IF(H20="","",IF(N20<=0,"COBRADA",IF(G20="","VIGENTE",IF(TODAY()<=G20,"VIGENTE",IF(TODAY()-G20<=30,"VENCIDA",IF(TODAY()-G20<=90,"CRÍTICA","CASTIGAR"))))))
B21: 12 | I21: =IF(H21<>"",H21*Supuestos!$C$11,"") | J21: =IF(H21<>"",H21*Supuestos!$C$12*Supuestos!$C$13,"") | K21: =IF(H21<>"",H21*Supuestos!$C$14,"") | L21: =IF(H21<>"",H21+I21-J21-K21,"") | N21: =IF(H21<>"",IF(M21<>"",L21-M21,L21),"") | O21: =IF(AND(H21<>"",N21>0,G21<>""),MAX(TODAY()-G21,0),"") | P21: =IF(H21="","",IF(N21<=0,"COBRADA",IF(G21="","VIGENTE",IF(TODAY()<=G21,"VIGENTE",IF(TODAY()-G21<=30,"VENCIDA",IF(TODAY()-G21<=90,"CRÍTICA","CASTIGAR"))))))
B22: 13 | I22: =IF(H22<>"",H22*Supuestos!$C$11,"") | J22: =IF(H22<>"",H22*Supuestos!$C$12*Supuestos!$C$13,"") | K22: =IF(H22<>"",H22*Supuestos!$C$14,"") | L22: =IF(H22<>"",H22+I22-J22-K22,"") | N22: =IF(H22<>"",IF(M22<>"",L22-M22,L22),"") | O22: =IF(AND(H22<>"",N22>0,G22<>""),MAX(TODAY()-G22,0),"") | P22: =IF(H22="","",IF(N22<=0,"COBRADA",IF(G22="","VIGENTE",IF(TODAY()<=G22,"VIGENTE",IF(TODAY()-G22<=30,"VENCIDA",IF(TODAY()-G22<=90,"CRÍTICA","CASTIGAR"))))))
... B209: 200 | I209: =IF(H209<>"",H209*Supuestos!$C$11,"") | J209: =IF(H209<>"",H209*Supuestos!$C$12*Supuestos!$C$13,"") | K209: =IF(H209<>"",H209*Supuestos!$C$14,"") | L209: =IF(H209<>"",H209+I209-J209-K209,"") | N209: =IF(H209<>"",IF(M209<>"",L209-M209,L209),"") | O209: =IF(AND(H209<>"",N209>0,G209<>""),MAX(TODAY()-G209,0),"") | P209: =IF(H209="","",IF(N209<=0,"COBRADA",IF(G209="","VIGENTE",IF(TODAY()<=G209,"VIGENTE",IF(TODAY()-G209<=30,"VENCIDA",IF(TODAY()-G209<=90,"CRÍTICA","CASTIGAR"))))))
B211: Estados: VIGENTE = dentro del plazo | VENCIDA = 1–30 días de mora | CRÍTICA = 31–90 días | CASTIGAR = +90 días (considerar provisión cartera incobrable per E.T. Art. 145)
B212: Nota: Las retenciones descontadas (col. J y K) son estimadas con las tarifas de Supuestos. Verifique el detalle por factura con su contador.
